 * Serving Flask app 'app'
 * Debug mode: on
INFO:werkzeug:WARNING: This is a development server. Do not use it in a production deployment. Use a production WSGI server instead.
 * Running on all addresses (0.0.0.0)
 * Running on http://127.0.0.1:5000
 * Running on http://172.31.128.5:5000
INFO:werkzeug:Press CTRL+C to quit
INFO:werkzeug: * Restarting with stat
WARNING:werkzeug: * Debugger is active!
INFO:werkzeug: * Debugger PIN: 512-271-518
INFO:werkzeug:172.31.128.5 - - [26/Mar/2025 15:13:06] "GET / HTTP/1.1" 302 -
INFO:werkzeug:172.31.128.5 - - [26/Mar/2025 15:13:06] "GET /login HTTP/1.1" 500 -
Traceback (most recent call last):
  File "/home/runner/workspace/.pythonlibs/lib/python3.11/site-packages/flask/app.py", line 1536, in __call__
    return self.wsgi_app(environ, start_response)
           ^^^^^^^^^^^^^^^^^^^^^^^^^^^^^^^^^^^^^^
  File "/home/runner/workspace/.pythonlibs/lib/python3.11/site-packages/flask/app.py", line 1514, in wsgi_app
    response = self.handle_exception(e)
               ^^^^^^^^^^^^^^^^^^^^^^^^
  File "/home/runner/workspace/.pythonlibs/lib/python3.11/site-packages/flask/app.py", line 1511, in wsgi_app
    response = self.full_dispatch_request()
               ^^^^^^^^^^^^^^^^^^^^^^^^^^^^
  File "/home/runner/workspace/.pythonlibs/lib/python3.11/site-packages/flask/app.py", line 919, in full_dispatch_request
    rv = self.handle_user_exception(e)
         ^^^^^^^^^^^^^^^^^^^^^^^^^^^^^
  File "/home/runner/workspace/.pythonlibs/lib/python3.11/site-packages/flask/app.py", line 917, in full_dispatch_request
    rv = self.dispatch_request()
         ^^^^^^^^^^^^^^^^^^^^^^^
  File "/home/runner/workspace/.pythonlibs/lib/python3.11/site-packages/flask/app.py", line 902, in dispatch_request
    return self.ensure_sync(self.view_functions[rule.endpoint])(**view_args)  # type: ignore[no-any-return]
           ^^^^^^^^^^^^^^^^^^^^^^^^^^^^^^^^^^^^^^^^^^^^^^^^^^^^^^^^^^^^^^^^^^^^^^^^^^^^^^^^^^^^^^^^^^^^^^^^
  File "/home/runner/workspace/routes.py", line 58, in login
    form = LoginForm()
           ^^^^^^^^^^^
  File "/home/runner/workspace/.pythonlibs/lib/python3.11/site-packages/wtforms/form.py", line 209, in __call__
    return type.__call__(cls, *args, **kwargs)
           ^^^^^^^^^^^^^^^^^^^^^^^^^^^^^^^^^^^
  File "/home/runner/workspace/.pythonlibs/lib/python3.11/site-packages/flask_wtf/form.py", line 73, in __init__
    super().__init__(formdata=formdata, **kwargs)
  File "/home/runner/workspace/.pythonlibs/lib/python3.11/site-packages/wtforms/form.py", line 287, in __init__
    self.process(formdata, obj, data=data, **kwargs)
  File "/home/runner/workspace/.pythonlibs/lib/python3.11/site-packages/wtforms/form.py", line 128, in process
    field.process(formdata, data, extra_filters=field_extra_filters)
  File "/home/runner/workspace/.pythonlibs/lib/python3.11/site-packages/wtforms/csrf/core.py", line 44, in process
    self.current_token = self.csrf_impl.generate_csrf_token(self)
                         ^^^^^^^^^^^^^^^^^^^^^^^^^^^^^^^^^^^^^^^^
  File "/home/runner/workspace/.pythonlibs/lib/python3.11/site-packages/flask_wtf/csrf.py", line 147, in generate_csrf_token
    return generate_csrf(
           ^^^^^^^^^^^^^^
  File "/home/runner/workspace/.pythonlibs/lib/python3.11/site-packages/flask_wtf/csrf.py", line 53, in generate_csrf
    session[field_name] = hashlib.sha1(os.urandom(64)).hexdigest()
  File "/home/runner/workspace/.pythonlibs/lib/python3.11/site-packages/flask/sessions.py", line 104, in _fail
    raise RuntimeError(
RuntimeError: The session is unavailable because no secret key was set.  Set the secret_key on the application to something unique and secret.
INFO:werkzeug:172.31.128.5 - - [26/Mar/2025 15:13:07] "GET /login?__debugger__=yes&cmd=resource&f=style.css HTTP/1.1" 200 -
INFO:werkzeug:172.31.128.5 - - [26/Mar/2025 15:13:07] "GET /login?__debugger__=yes&cmd=resource&f=debugger.js HTTP/1.1" 200 -
